<?xml version="1.0" ?>
<!-- =================================================================================== -->
<!-- |    This document was autogenerated by xacro from src/visual_model/urdf/hexapod_leg.xacro | -->
<!-- |    EDITING THIS FILE BY HAND IS NOT RECOMMENDED                                 | -->
<!-- =================================================================================== -->
<robot name="hexapod_leg" xmlns:xacro="http://www.ros.org/wiki/xacro">
  <link name="base_link"/>
  <joint name="base_joint" type="fixed">
    <parent link="base_link"/>
    <child link="body"/>
    <origin rpy="0 0 0" xyz="0 0 0"/>
  </joint>
  <link name="body">
    <visual>
      <geometry>
        <box size="0.205 0.12 0.04"/>
      </geometry>
      <origin rpy="0 0 0" xyz="0 0 0"/>
      <material name="white">
        <color rgba="1 1 1 1"/>
      </material>
    </visual>
    <collision>
      <geometry>
        <box size="0.205 0.12 0.04"/>
      </geometry>
    </collision>
    <inertial>
      <mass value="0.3"/>
      <inertia ixx="1.0" ixy="0.0" ixz="0.0" iyy="1.0" iyz="0.0" izz="1.0"/>
    </inertial>
  </link>
  <link name="leg_center_1"/>
  <joint name="leg_center_joint" type="fixed">
    <parent link="body"/>
    <child link="leg_center_1"/>
    <origin rpy="0 0 -1.57" xyz="0 -0.0725 0"/>
  </joint>
  <link name="leg_L1">
    <visual>
      <geometry>
        <box size="0.034 0.02 0.02"/>
      </geometry>
      <origin rpy="0 0 0" xyz="0.017 0 0"/>
      <material name="yellow">
        <color rgba="255 255 0 1"/>
      </material>
    </visual>
    <collision>
      <geometry>
        <box size="0.034 0.02 0.02"/>
      </geometry>
    </collision>
    <inertial>
      <mass value="0.158"/>
      <inertia ixx="1.0" ixy="0.0" ixz="0.0" iyy="1.0" iyz="0.0" izz="1.0"/>
    </inertial>
  </link>
  <joint name="body_to_leg1" type="revolute">
    <parent link="leg_center_1"/>
    <child link="leg_L1"/>
    <axis xyz="0 0 -1"/>
    <origin rpy="0 0 0" xyz="0 0 0"/>
    <limit effort="1000.0" lower="-1.0" upper="1.0" velocity="0.5"/>
  </joint>
  <!--
    <link name="leg_L2">
      <visual>
        <geometry>
          <box size="${L2_length} ${L_width} ${L_width}"/>
        </geometry>
        <origin rpy="0 0 0" xyz="${L2_length/2} 0 0"/>
        <material name="yellow">
          <color rgba="255 0 255 1"/>
        </material>
      </visual>
      <collision>
        <geometry>
          <box size="${L2_length} ${L_width} ${L_width}"/>
        </geometry>
      </collision>
      <xacro:default_inertial mass="${L2_mass}"/>
    </link>

    <joint name="leg1_to_leg2" type="revolute">
      <parent link="leg_L1"/>
      <child link="leg_L2"/>
      <origin rpy="0 0 0" xyz="0 -0.5 0"/>
      <limit effort ="1000.0" lower="-1.0" upper="1.0" velocity="0.5"/>
    </joint>
-->
</robot>

